Workbook

Sheet Banking Sector - PSU
B2: PSU BANKING SECTOR INDIA
I4: WEEK 1 | AI4: WEEK 2 | BH4: WEEK 3 | CB4: WEEK 4 | DA4: WEEK 5 | DZ4: WEEK 6 | EY4: WEEK 7 | FS4: WEEK 8 | GR4: WEEK 9
E5: 46142 | I5: 11-05-2026 (Mon) | O5: 12-05-2026 (Tues) | T5: 13-05-2026 (Wed) | Y5: 14-05-2026 (Thurs) | AD5: 15-05-2026 (Fri) | AI5: 18-05-2026 (Mon) | AN5: 19-05-2026 (Tues) | AS5: 20-05-2026 (Wed) | AX5: 21-05-2026 (Thurs) | BC5: 22-05-2026 (Fri) | BH5: 25-05-2026 (Mon) | BM5: 26-05-2026 (Tues) | BR5: 27-05-2026 (Wed) | BW5: 29-05-2026 (Fri) | CB5: 01-06-2026 (Mon) | CG5: 02-06-2026 (Tues) | CL5: 03-06-2026 (Wed) | CQ5: 04-06-2026 (Thurs) | CV5: 05-06-2026 (Fri) | DA5: 08-06-2026 (Mon) | DF5: 09-06-2026 (Tues) | DK5: 10-06-2026 (Wed) | DP5: 11-06-2026 (Thurs) | DU5: 12-06-2026 (Fri) | DZ5: 15-06-2026 (Mon) | EE5: 16-06-2026 (Tues) | EJ5: 17-06-2026 (Wed) | EO5: 18-06-2026 (Thurs) | ET5: 19-06-2026 (Fri) | EY5: 22-06-2026 (Mon) | FD5: 23-06-2026 (Tues) | FI5: 24-06-2026 (Wed) | FN5: 25-06-2026 (Thurs) | FS5: 29-06-2026 (Mon) | FX5: 30-06-2026 (Tues) | GC5: 01-07-2026 (Wed) | GH5: 02-07-2026 (Thurs) | GM5: 03-07-2026 (Fri) | GR5: 06-07-2026 (Mon) | GW5: 07-07-2026 (Tues) | HB5: 08-07-2026 (Wed) | HG5: 09-07-2026 (Thurs) | HL5: 10-07-2026 (Fri)
B6: S. No. | C6: Company Name | D6: Symbol | E6: Price (₹) | F6: Market Cap (₹ Cr.) | G6: Days weight | H6: PE Ratio | I6: Closing Price | J6: Percentage Change | K6: Net Change | L6: No. Of Shares | M6: New Market Cap | N6: New Weight | O6: Closing Price | P6: Percentage Change | Q6: Net Change | R6: New Market Cap | S6: New Weight | T6: Closing Price | U6: Percentage Change | V6: Net Change | W6: New Market Cap | X6: New Weight | Y6: Closing Price | Z6: Percentage Change | AA6: Net Change | AB6: New Market Cap | AC6: New Weight | AD6: Closing Price | AE6: Percentage Change | AF6: Net Change | AG6: New Market Cap | AH6: New Weight | AI6: Closing Price | AJ6: Percentage Change | AK6: Net Change | AL6: New Market Cap | AM6: New Weight | AN6: Closing Price | AO6: Percentage Change | AP6: Net Change | AQ6: New Market Cap | AR6: New Weight | AS6: Closing Price | AT6: Percentage Change | AU6: Net Change | AV6: New Market Cap | AW6: New Weight | AX6: Closing Price | AY6: Percentage Change | AZ6: Net Change | BA6: New Market Cap | BB6: New Weight | BC6: Closing Price | BD6: Percentage Change | BE6: Net Change | BF6: New Market Cap | BG6: New Weight | BH6: Closing Price | BI6: Percentage Change | BJ6: Net Change | BK6: New Market Cap | BL6: New Weight | BM6: Closing Price | BN6: Percentage Change | BO6: Net Change | BP6: New Market Cap | BQ6: New Weight | BR6: Closing Price | BS6: Percentage Change | BT6: Net Change | BU6: New Market Cap | BV6: New Weight | BW6: Closing Price | BX6: Percentage Change | BY6: Net Change | BZ6: New Market Cap | CA6: New Weight | CB6: Closing Price | CC6: Percentage Change | CD6: Net Change | CE6: New Market Cap | CF6: New Weight | CG6: Closing Price | CH6: Percentage Change | CI6: Net Change | CJ6: New Market Cap | CK6: New Weight | CL6: Closing Price | CM6: Percentage Change | CN6: Net Change | CO6: New Market Cap | CP6: New Weight | CQ6: Closing Price | CR6: Percentage Change | CS6: Net Change | CT6: New Market Cap | CU6: New Weight | CV6: Closing Price | CW6: Percentage Change | CX6: Net Change | CY6: New Market Cap | CZ6: New Weight | DA6: Closing Price | DB6: Percentage Change | DC6: Net Change | DD6: New Market Cap | DE6: New Weight | DF6: Closing Price | DG6: Percentage Change | DH6: Net Change | DI6: New Market Cap | DJ6: New Weight | DK6: Closing Price | DL6: Percentage Change | DM6: Net Change | DN6: New Market Cap | DO6: New Weight | DP6: Closing Price | DQ6: Percentage Change | DR6: Net Change | DS6: New Market Cap | DT6: New Weight | DU6: Closing Price | DV6: Percentage Change | DW6: Net Change | DX6: New Market Cap | DY6: New Weight | DZ6: Closing Price | EA6: Percentage Change | EB6: Net Change | EC6: New Market Cap | ED6: New Weight | EE6: Closing Price | EF6: Percentage Change | EG6: Net Change | EH6: New Market Cap | EI6: New Weight | EJ6: Closing Price | EK6: Percentage Change | EL6: Net Change | EM6: New Market Cap | EN6: New Weight | EO6: Closing Price | EP6: Percentage Change | EQ6: Net Change | ER6: New Market Cap | ES6: New Weight | ET6: Closing Price | EU6: Percentage Change | EV6: Net Change | EW6: New Market Cap | EX6: New Weight | EY6: Closing Price | EZ6: Percentage Change | FA6: Net Change | FB6: New Market Cap | FC6: New Weight | FD6: Closing Price | FE6: Percentage Change | FF6: Net Change | FG6: New Market Cap | FH6: New Weight | FI6: Closing Price | FJ6: Percentage Change | FK6: Net Change | FL6: New Market Cap | FM6: New Weight | FN6: Closing Price | FO6: Percentage Change | FP6: Net Change | FQ6: New Market Cap | FR6: New Weight | FS6: Closing Price | FT6: Percentage Change | FU6: Net Change | FV6: New Market Cap | FW6: New Weight | FX6: Closing Price | FY6: Percentage Change | FZ6: Net Change | GA6: New Market Cap | GB6: New Weight | GC6: Closing Price | GD6: Percentage Change | GE6: Net Change | GF6: New Market Cap | GG6: New Weight | GH6: Closing Price | GI6: Percentage Change | GJ6: Net Change | GK6: New Market Cap | GL6: New Weight | GM6: Closing Price | GN6: Percentage Change | GO6: Net Change | GP6: New Market Cap | GQ6: New Weight | GR6: Closing Price | GS6: Percentage Change | GT6: Net Change | GU6: New Market Cap | GV6: New Weight | GW6: Closing Price | GX6: Percentage Change | GY6: Net Change | GZ6: New Market Cap | HA6: New Weight | HB6: Closing Price | HC6: Percentage Change | HD6: Net Change | HE6: New Market Cap | HF6: New Weight | HG6: Closing Price | HH6: Percentage Change | HI6: Net Change | HJ6: New Market Cap | HK6: New Weight | HL6: Closing Price | HM6: Percentage Change | HN6: Net Change | HO6: New Market Cap | HP6: New Weight
B7: 1 | C7: State Bank of India (SBI) | D7: SBIN | E7: 1068 | F7: 986245 | G7: =(F7/$F$19) -> 0.52256153 | H7: 12.17 | I7: 973.6 | J7: =(I7-E7)/E7 -> -0.088389513 | K7: =G7*J7 -> -0.046188959 | L7: =F7/E7 -> 923.45037 | M7: =L7*I7 -> 899071.28 | N7: =(M7/$M$19) -> 0.50234922 | O7: 974.6 | P7: =(O7-I7)/I7 -> 0.0010271159 | Q7: =N7*P7 -> 0.00051597086 | R7: =O7*L7 -> 899994.74 | S7: =R7/$R$19 -> 0.50730024 | T7: 970.45 | U7: =(T7-O7)/O7 -> -0.0042581572 | V7: =U7*S7 -> -0.0021601642 | W7: =T7*$L7 -> 896162.42 | X7: =W7/$W$19 -> 0.50592414 | Y7: 979.9 | Z7: =(Y7-T7)/T7 -> 0.0097377505 | AA7: =Z7*X7 -> 0.0049265631 | AB7: =Y7*$L7 -> 904889.02 | AC7: =AB7/$AB$19 -> 0.50502143 | AD7: 963.2 | AE7: =(AD7-Y7)/Y7 -> -0.017042555 | AF7: =AE7*AC7 -> -0.0086068557 | AG7: =AD7*$L7 -> 889467.4 | AH7: =AG7/$AG$19 -> 0.50492384 | AI7: 939.4 | AJ7: =(AI7-AD7)/AD7 -> -0.024709302 | AK7: =AJ7*AH7 -> -0.012476316 | AL7: =AI7*$L7 -> 867489.28 | AM7: =AL7/$AL$19 -> 0.50275626 | AN7: 948.8 | AO7: =(AN7-AI7)/AI7 -> 0.010006387 | AP7: =AO7*AM7 -> 0.0050307737 | AQ7: =AN7*$L7 -> 876169.72 | AR7: =AQ7/$AQ$19 -> 0.50248693 | AS7: 950.9 | AT7: =(AS7-AN7)/AN7 -> 0.0022133221 | AU7: =AT7*AR7 -> 0.0011121654 | AV7: =AS7*$L7 -> 878108.96 | AW7: =AV7/$AV$19 -> 0.50323621 | AX7: 950.9 | AY7: =(AX7-AS7)/AS7 -> 0 | AZ7: =AY7*AW7 -> 0 | BA7: =AX7*$L7 -> 878108.96 | BB7: =BA7/$BA$19 -> 0.50210583 | BC7: 949.2 | BD7: =(BC7-AX7)/AX7 -> -0.00178778 | BE7: =BD7*BB7 -> -0.00089765477 | BF7: =BC7*$L7 -> 876539.1 | BG7: =BF7/$BF$19 -> 0.50146097 | BH7: 969.6 | BI7: =(BH7-BC7)/BC7 -> 0.021491783 | BJ7: =BI7*BG7 -> 0.01077729 | BK7: =BH7*$L7 -> 895377.48 | BL7: =BK7/$BK$19 -> 0.49937826 | BM7: 968.6 | BN7: =(BM7-BH7)/BH7 -> -0.0010313531 | BO7: =BN7*BL7 -> -0.00051503533 | BP7: =BM7*$L7 -> 894454.03 | BQ7: =BP7/$BP$19 -> 0.50046484 | BR7: 967.8 | BS7: =(BR7-BM7)/BM7 -> -0.00082593434 | BT7: =BS7*BQ7 -> -0.00041335109 | BU7: =BR7*$L7 -> 893715.27 | BV7: =BU7/$BU$19 -> 0.49919925 | BW7: 964.4 | BX7: =(BW7-BR7)/BR7 -> -0.0035131225 | BY7: =BX7*BV7 -> -0.0017537481 | BZ7: =BW7*$L7 -> 890575.54 | CA7: =BZ7/$BZ$19 -> 0.50144743 | CB7: 954.1 | CC7: =(CB7-BW7)/BW7 -> -0.010680216 | CD7: =CC7*CA7 -> -0.0053555667 | CE7: =CB7*$L7 -> 881064 | CF7: =CE7/$CE$19 -> 0.50422423 | CG7: 956.65 | CH7: =(CG7-CB7)/CB7 -> 0.0026726758 | CI7: =CH7*CF7 -> 0.0013476279 | CJ7: =CG7*$L7 -> 883418.8 | CK7: =CJ7/$CJ$19 -> 0.49931446 | CL7: 954.1 | CM7: =(CL7-CG7)/CG7 -> -0.0026655517 | CN7: =CM7*CK7 -> -0.0013309485 | CO7: =CL7*$L7 -> 881064 | CP7: =CO7/$CO$19 -> 0.49860177 | CQ7: 979.25 | CR7: =(CQ7-CL7)/CL7 -> 0.02635992 | CS7: =CR7*CP7 -> 0.013143103 | CT7: =CQ7*$L7 -> 904288.78 | CU7: =CT7/$CT$19 -> 0.50412026 | CV7: 978 | CW7: =(CV7-CQ7)/CQ7 -> -0.0012764871 | CX7: =CW7*CW7 -> 1.6294193e-06 | CY7: =CV7*$L7 -> 903134.47 | CZ7: =CY7/$CY$19 -> 0.50417757 | DA7: 981.95 | DB7: =(DA7-CV7)/CV7 -> 0.0040388548 | DC7: =DB7*CZ7 -> 0.0020363 | DD7: =DA7*$L7 -> 906782.1 | DE7: =DD7/$DD$19 -> 0.50794075 | DF7: 1002.7 | DG7: =(DF7-DA7)/DA7 -> 0.021131422 | DH7: =DG7*DE7 -> 0.01073351 | DI7: =DF7*$L7 -> 925943.69 | DJ7: =DI7/$DI$19 -> 0.50305786 | DK7: 1003.25 | DL7: =(DK7-DF7)/DF7 -> 0.000548519 | DM7: =DL7*DJ7 -> 0.00027593679 | DN7: =DK7*$L7 -> 926451.59 | DO7: =DN7/$DN$19 -> 0.50859775 | DP7: 1000.7 | DQ7: =(DP7-DK7)/DK7 -> -0.0025417393 | DR7: =DQ7*DO7 -> -0.0012927229 | DS7: =DP7*$L7 -> 924096.79 | DT7: =DS7/$DS$19 -> 0.51123715 | DU7: 1017.15 | DV7: =(DU7-DP7)/DP7 -> 0.016438493 | DW7: =DV7*DV7 -> 0.00027022405 | DX7: =DU7*$L7 -> 939287.55 | DY7: =DX7/$DX$19 -> 0.5096491 | DZ7: 1020.85 | EA7: =(DZ7-DU7)/DU7 -> 0.0036376149 | EB7: =EA7*DY7 -> 0.0018539072 | EC7: =DZ7*$L7 -> 942704.31 | ED7: =EC7/$EC$19 -> 0.50850706 | EE7: 1015.3 | EF7: =(EE7-DZ7)/DZ7 -> -0.0054366459 | EG7: =EF7*ED7 -> -0.0027645729 | EH7: =EE7*$L7 -> 937579.17 | EI7: =EH7/$EH$19 -> 0.50718644 | EJ7: 1026.5 | EK7: =(EJ7-EE7)/EE7 -> 0.011031222 | EL7: =EK7*EI7 -> 0.0055948863 | EM7: =EJ7*$L7 -> 947921.81 | EN7: =EM7/$EM$19 -> 0.50386615 | EO7: 1042.7 | EP7: =(EO7-EJ7)/EJ7 -> 0.015781783 | EQ7: =EP7*EN7 -> 0.0079519061 | ER7: =EO7*$L7 -> 962881.71 | ES7: =ER7/$ER$19 -> 0.50757381 | ET7: 1035.1 | EU7: =(ET7-EO7)/EO7 -> -0.0072887695 | EV7: =EU7*EU7 -> 5.3126161e-05 | EW7: =ET7*$L7 -> 955863.48 | EX7: =EW7/$EW$19 -> 0.50709839 | EY7: 1040.75 | EZ7: =(EY7-ET7)/ET7 -> 0.0054584098 | FA7: =EZ7*EX7 -> 0.0027679508 | FB7: =EY7*$L7 -> 961080.98 | FC7: =FB7/$FB$19 -> 0.50736996 | FD7: 1024.2 | FE7: =(FD7-EY7)/EY7 -> -0.015901994 | FF7: =FE7*FC7 -> -0.008068194 | FG7: =FD7*$L7 -> 945797.87 | FH7: =FG7/$FG$19 -> 0.50835859 | FI7: 1034.6 | FJ7: =(FI7-FD7)/FD7 -> 0.010154267 | FK7: =FJ7*FH7 -> 0.0051620087 | FL7: =FI7*$L7 -> 955401.76 | FM7: =FL7/$FL$19 -> 0.51052637 | FN7: 1045 | FO7: =(FN7-FI7)/FI7 -> 0.010052194 | FP7: =FO7*FM7 -> 0.0051319102 | FQ7: =FN7*$L7 -> 965005.64 | FR7: =FQ7/$FQ$19 -> 0.51406065 | FS7: 1036.1 | FT7: =(FS7-FN7)/FN7 -> -0.0085167464 | FU7: =FT7*FR7 -> -0.0043781242 | FV7: =FS7*$L7 -> 956786.93 | FW7: =FV7/$FQ$19 -> 0.50968252 | FX7: 1026.9 | FY7: =(FX7-FS7)/FS7 -> -0.0088794518 | FZ7: =FY7*FW7 -> -0.0045257014 | GA7: =FX7*$L7 -> 948291.19 | GB7: =GA7/$GA$19 -> 0.51328814 | GC7: 1047.4 | GD7: =(GC7-FX7)/FX7 -> 0.019962995 | GE7: =GD7*GB7 -> 0.010246769 | GF7: =GC7*$L7 -> 967221.92 | GG7: =GF7/$GF$19 -> 0.51966887 | GH7: 1051.6 | GI7: =(GH7-GC7)/GC7 -> 0.0040099293 | GJ7: =GI7*GG7 -> 0.0020838354 | GK7: =GH7*$L7 -> 971100.41 | GL7: =GK7/$GK$19 -> 0.52077716 | GM7: 1040 | GN7: =(GM7-GH7)/GH7 -> -0.01103081 | GO7: =GN7*GN7 -> 0.00012167877 | GP7: =GM7*$L7 -> 960388.39 | GQ7: =GP7/$GP$19 -> 0.52245499 | GR7: 1037.7 | GS7: =(GR7-GM7)/GM7 -> -0.0022115385 | GT7: =GS7*GQ7 -> -0.0011554293 | GU7: =GR7*$L7 -> 958264.45 | GV7: =GU7/$GU$19 -> 0.52429642 | GW7: 1038.1 | GX7: =(GW7-GR7)/GR7 -> 0.00038546786 | GY7: =GX7*GV7 -> 0.00020209942 | GZ7: =GW7*$L7 -> 958633.83 | HA7: =GZ7/$GZ$19 -> 0.52596206 | HB7: 1016.9 | HC7: =(HB7-GW7)/GW7 -> -0.020421925 | HD7: =HC7*HA7 -> -0.010741158 | HE7: =HB7*$L7 -> 939056.69 | HF7: =HE7/$HE$19 -> 0.52830364 | HG7: 1022.1 | HH7: =(HG7-HB7)/HB7 -> 0.0051135805 | HI7: =HH7*HF7 -> 0.0027015232 | HJ7: =HG7*$L7 -> 943858.63 | HK7: =HJ7/$HJ$19 -> 0.52360454 | HL7: 1036 | HM7: =(HL7-HG7)/HG7 -> 0.013599452 | HN7: =HM7*HM7 -> 0.0001849451 | HO7: =HL7*$L7 -> 956694.59 | HP7: =HO7/$HO$19 -> 0.51959155
B8: 2 | C8: Bank of Baroda (BOB) | D8: BANKBARODA | E8: 263 | F8: 136245 | G8: =(F8/$F$19) -> 0.07218936 | H8: 7 | I8: 266 | J8: =(I8-E8)/E8 -> 0.011406844 | K8: =G8*J8 -> 0.00082345277 | L8: =F8/E8 -> 518.04183 | M8: =L8*I8 -> 137799.13 | N8: =(M8/$M$19) -> 0.076994211 | O8: 259.95 | P8: =(O8-I8)/I8 -> -0.022744361 | Q8: =N8*P8 -> -0.0017511841 | R8: =O8*L8 -> 134664.97 | S8: =R8/$R$19 -> 0.075906636 | T8: 261.65 | U8: =(T8-O8)/O8 -> 0.0065397192 | V8: =U8*S8 -> 0.00049640808 | W8: =T8*$L8 -> 135545.64 | X8: =W8/$W$19 -> 0.076521635 | Y8: 267.8 | Z8: =(Y8-T8)/T8 -> 0.023504682 | AA8: =Z8*X8 -> 0.0017986167 | AB8: =Y8*$L8 -> 138731.6 | AC8: =AB8/$AB$19 -> 0.077426546 | AD8: 261.4 | AE8: =(AD8-Y8)/Y8 -> -0.023898432 | AF8: =AE8*AC8 -> -0.001850373 | AG8: =AD8*$L8 -> 135416.13 | AH8: =AG8/$AG$19 -> 0.076871659 | AI8: 260.05 | AJ8: =(AI8-AD8)/AD8 -> -0.0051644989 | AK8: =AJ8*AH8 -> -0.00039700359 | AL8: =AI8*$L8 -> 134716.78 | AM8: =AL8/$AL$19 -> 0.078075549 | AN8: 260.6 | AO8: =(AN8-AI8)/AI8 -> 0.0021149779 | AP8: =AO8*AM8 -> 0.00016512806 | AQ8: =AN8*$L8 -> 135001.7 | AR8: =AQ8/$AQ$19 -> 0.07742403 | AS8: 263.55 | AT8: =(AS8-AN8)/AN8 -> 0.011320031 | AU8: =AT8*AR8 -> 0.00087644239 | AV8: =AS8*$L8 -> 136529.92 | AW8: =AV8/$AV$19 -> 0.078244049 | AX8: 263.1 | AY8: =(AX8-AS8)/AS8 -> -0.0017074559 | AZ8: =AY8*AW8 -> -0.00013359826 | BA8: =AX8*$L8 -> 136296.8 | BB8: =BA8/$BA$19 -> 0.077934999 | BC8: 265.4 | BD8: =(BC8-AX8)/AX8 -> 0.0087419232 | BE8: =BD8*BB8 -> 0.00068130177 | BF8: =BC8*$L8 -> 137488.3 | BG8: =BF8/$BF$19 -> 0.078655952 | BH8: 272.25 | BI8: =(BH8-BC8)/BC8 -> 0.025810098 | BJ8: =BI8*BG8 -> 0.0020301178 | BK8: =BH8*$L8 -> 141036.89 | BL8: =BK8/$BK$19 -> 0.078660405 | BM8: 270.5 | BN8: =(BM8-BH8)/BH8 -> -0.0064279155 | BO8: =BN8*BL8 -> -0.00050562244 | BP8: =BM8*$L8 -> 140130.31 | BQ8: =BP8/$BP$19 -> 0.0784057 | BR8: 270.95 | BS8: =(BR8-BM8)/BM8 -> 0.001663586 | BT8: =BS8*BQ8 -> 0.00013043462 | BU8: =BR8*$L8 -> 140363.43 | BV8: =BU8/$BU$19 -> 0.078402286 | BW8: 268.5 | BX8: =(BW8-BR8)/BR8 -> -0.0090422587 | BY8: =BX8*BV8 -> -0.00070893375 | BZ8: =BW8*$L8 -> 139094.23 | CA8: =BZ8/$BZ$19 -> 0.078318391 | CB8: 264.35 | CC8: =(CB8-BW8)/BW8 -> -0.015456238 | CD8: =CC8*CA8 -> -0.0012105077 | CE8: =CB8*$L8 -> 136944.36 | CF8: =CE8/$CE$19 -> 0.078371904 | CG8: 265.8 | CH8: =(CG8-CB8)/CB8 -> 0.0054851523 | CI8: =CH8*CF8 -> 0.00042988182 | CJ8: =CG8*$L8 -> 137695.52 | CK8: =CJ8/$CJ$19 -> 0.077826465 | CL8: 268.85 | CM8: =(CL8-CG8)/CG8 -> 0.011474793 | CN8: =CM8*CK8 -> 0.00089304258 | CO8: =CL8*$L8 -> 139275.54 | CP8: =CO8/$CO$19 -> 0.078817241 | CQ8: 271.3 | CR8: =(CQ8-CL8)/CL8 -> 0.0091128882 | CS8: =CR8*CP8 -> 0.0007182527 | CT8: =CQ8*$L8 -> 140544.75 | CU8: =CT8/$CT$19 -> 0.078350475 | CV8: 263.7 | CW8: =(CV8-CQ8)/CQ8 -> -0.028013269 | CX8: =CW8*CW8 -> 0.00078474326 | CY8: =CV8*$L8 -> 136607.63 | CZ8: =CY8/$CY$19 -> 0.076261626 | DA8: 259.25 | DB8: =(DA8-CV8)/CV8 -> -0.016875237 | DC8: =DB8*CZ8 -> -0.001286933 | DD8: =DA8*$L8 -> 134302.34 | DE8: =DD8/$DD$19 -> 0.075230459 | DF8: 273.8 | DG8: =(DF8-DA8)/DA8 -> 0.056123433 | DH8: =DG8*DE8 -> 0.0042221916 | DI8: =DF8*$L8 -> 141839.85 | DJ8: =DI8/$DI$19 -> 0.077060465 | DK8: 269.3 | DL8: =(DK8-DF8)/DF8 -> -0.016435354 | DM8: =DL8*DJ8 -> -0.0012665161 | DN8: =DK8*$L8 -> 139508.66 | DO8: =DN8/$DN$19 -> 0.076586616 | DP8: 267.6 | DQ8: =(DP8-DK8)/DK8 -> -0.0063126625 | DR8: =DQ8*DO8 -> -0.00048346546 | DS8: =DP8*$L8 -> 138627.99 | DT8: =DS8/$DS$19 -> 0.076693026 | DU8: 274.75 | DV8: =(DU8-DP8)/DP8 -> 0.026718984 | DW8: =DV8*DV8 -> 0.00071390408 | DX8: =DU8*$L8 -> 142331.99 | DY8: =DX8/$DX$19 -> 0.077228077 | DZ8: 276.05 | EA8: =(DZ8-DU8)/DU8 -> 0.0047315742 | EB8: =EA8*DY8 -> 0.00036541038 | EC8: =DZ8*$L8 -> 143005.45 | ED8: =EC8/$EC$19 -> 0.077139012 | EE8: 275.35 | EF8: =(EE8-DZ8)/DZ8 -> -0.0025357725 | EG8: =EF8*ED8 -> -0.00019560699 | EH8: =EE8*$L8 -> 142642.82 | EI8: =EH8/$EH$19 -> 0.077163086 | EJ8: 281.85 | EK8: =(EJ8-EE8)/EE8 -> 0.023606319 | EL8: =EK8*EI8 -> 0.0018215364 | EM8: =EJ8*$L8 -> 146010.09 | EN8: =EM8/$EM$19 -> 0.077611402 | EO8: 283 | EP8: =(EO8-EJ8)/EJ8 -> 0.0040801845 | EQ8: =EP8*EN8 -> 0.00031666884 | ER8: =EO8*$L8 -> 146605.84 | ES8: =ER8/$ER$19 -> 0.077281854 | ET8: 281.05 | EU8: =(ET8-EO8)/EO8 -> -0.0068904594 | EV8: =EU8*EU8 -> 4.747843e-05 | EW8: =ET8*$L8 -> 145595.65 | EX8: =EW8/$EW$19 -> 0.077240446 | EY8: 286.05 | EZ8: =(EY8-ET8)/ET8 -> 0.017790429 | FA8: =EZ8*EX8 -> 0.0013741407 | FB8: =EY8*$L8 -> 148185.86 | FC8: =FB8/$FB$19 -> 0.078229679 | FD8: 277.8 | FE8: =(FD8-EY8)/EY8 -> -0.028841112 | FF8: =FE8*FC8 -> -0.0022562309 | FG8: =FD8*$L8 -> 143912.02 | FH8: =FG8/$FG$19 -> 0.077351528 | FI8: 279.9 | FJ8: =(FI8-FD8)/FD8 -> 0.0075593952 | FK8: =FJ8*FH8 -> 0.00058473077 | FL8: =FI8*$L8 -> 144999.91 | FM8: =FL8/$FL$19 -> 0.07748183 | FN8: 279.15 | FO8: =(FN8-FI8)/FI8 -> -0.0026795284 | FP8: =FO8*FM8 -> -0.00020761476 | FQ8: =FN8*$L8 -> 144611.38 | FR8: =FQ8/$FQ$19 -> 0.077034801 | FS8: 272.8 | FT8: =(FS8-FN8)/FN8 -> -0.022747627 | FU8: =FT8*FR8 -> -0.0017523589 | FV8: =FS8*$L8 -> 141321.81 | FW8: =FV8/$FQ$19 -> 0.075282442 | FX8: 271.65 | FY8: =(FX8-FS8)/FS8 -> -0.0042155425 | FZ8: =FY8*FW8 -> -0.00031735634 | GA8: =FX8*$L8 -> 140726.06 | GB8: =GA8/$GA$19 -> 0.07617177 | GC8: 252.2 | GD8: =(GC8-FX8)/FX8 -> -0.071599485 | GE8: =GD8*GB8 -> -0.0054538594 | GF8: =GC8*$L8 -> 130650.15 | GG8: =GF8/$GF$19 -> 0.070195695 | GH8: 249.95 | GI8: =(GH8-GC8)/GC8 -> -0.0089214909 | GJ8: =GI8*GG8 -> -0.00062625025 | GK8: =GH8*$L8 -> 129484.55 | GL8: =GK8/$GK$19 -> 0.069439367 | GM8: 247.85 | GN8: =(GM8-GH8)/GH8 -> -0.0084016803 | GO8: =GN8*GN8 -> 7.0588232e-05 | GP8: =GM8*$L8 -> 128396.67 | GQ8: =GP8/$GP$19 -> 0.069848282 | GR8: 249.95 | GS8: =(GR8-GM8)/GM8 -> 0.0084728667 | GT8: =GS8*GQ8 -> 0.00059181518 | GU8: =GR8*$L8 -> 129484.55 | GV8: =GU8/$GU$19 -> 0.070845045 | GW8: 247.85 | GX8: =(GW8-GR8)/GR8 -> -0.0084016803 | GY8: =GX8*GV8 -> -0.00059521742 | GZ8: =GW8*$L8 -> 128396.67 | HA8: =GZ8/$GZ$19 -> 0.07044585 | HB8: 240.45 | HC8: =(HB8-GW8)/GW8 -> -0.029856768 | HD8: =HC8*HA8 -> -0.0021032854 | HE8: =HB8*$L8 -> 124563.16 | HF8: =HE8/$GF$19 -> 0.066925277 | HG8: 250.95 | HH8: =(HG8-HB8)/HB8 -> 0.043668122 | HI8: =HH8*HF8 -> 0.0029225012 | HJ8: =HG8*$L8 -> 130002.6 | HK8: =HJ8/$HJ$19 -> 0.072118798 | HL8: 244.6 | HM8: =(HL8-HG8)/HG8 -> -0.025303845 | HN8: =HM8*HM8 -> 0.00064028459 | HO8: =HL8*$L8 -> 126713.03 | HP8: =HO8/$HO$19 -> 0.068819267
B9: 3 | C9: Union Bank of India | D9: UNIONBANK | E9: 166 | F9: 126672 | G9: =(F9/$F$19) -> 0.067117109 | H9: 6.52 | I9: 163.81 | J9: =(I9-E9)/E9 -> -0.013192771 | K9: =G9*J9 -> -0.00088546066 | L9: =F9/E9 -> 763.08434 | M9: =L9*I9 -> 125000.85 | N9: =(M9/$M$19) -> 0.069843269 | O9: 162.19 | P9: =(O9-I9)/I9 -> -0.0098895061 | Q9: =N9*P9 -> -0.00069071544 | R9: =O9*L9 -> 123764.65 | S9: =R9/$R$19 -> 0.069762448 | T9: 162.9 | U9: =(T9-O9)/O9 -> 0.0043775818 | V9: =U9*S9 -> 0.00030539083 | W9: =T9*$L9 -> 124306.44 | X9: =W9/$W$19 -> 0.070176596 | Y9: 164.9 | Z9: =(Y9-T9)/T9 -> 0.012277471 | AA9: =Z9*X9 -> 0.00086159111 | AB9: =Y9*$L9 -> 125832.61 | AC9: =AB9/$AB$19 -> 0.070227577 | AD9: 161.94 | AE9: =(AD9-Y9)/Y9 -> -0.017950273 | AF9: =AE9*AC9 -> -0.0012606042 | AG9: =AD9*$L9 -> 123573.88 | AH9: =AG9/$AG$19 -> 0.070149167 | AI9: 158.89 | AJ9: =(AI9-AD9)/AD9 -> -0.018834136 | AK9: =AJ9*AH9 -> -0.001321199 | AL9: =AI9*$L9 -> 121246.47 | AM9: =AL9/$AL$19 -> 0.070268789 | AN9: 158.96 | AO9: =(AN9-AI9)/AI9 -> 0.00044055636 | AP9: =AO9*AM9 -> 3.0957362e-05 | AQ9: =AN9*$L9 -> 121299.89 | AR9: =AQ9/$AQ$19 -> 0.069565983 | AS9: 159 | AT9: =(AS9-AN9)/AN9 -> 0.00025163563 | AU9: =AT9*AR9 -> 1.750528e-05 | AV9: =AS9*$L9 -> 121330.41 | AW9: =AV9/$AV$19 -> 0.069533347 | AX9: 160.12 | AY9: =(AX9-AS9)/AS9 -> 0.0070440252 | AZ9: =AY9*AW9 -> 0.00048979465 | BA9: =AX9*$L9 -> 122185.06 | BB9: =BA9/$BA$19 -> 0.069865855 | BC9: 160.72 | BD9: =(BC9-AX9)/AX9 -> 0.0037471896 | BE9: =BD9*BB9 -> 0.00026180061 | BF9: =BC9*$L9 -> 122642.91 | BG9: =BF9/$BF$19 -> 0.070163026 | BH9: 168.87 | BI9: =(BH9-BC9)/BC9 -> 0.050709308 | BJ9: =BI9*BG9 -> 0.0035579185 | BK9: =BH9*$L9 -> 128862.05 | BL9: =BK9/$BK$19 -> 0.071870142 | BM9: 167.55 | BN9: =(BM9-BH9)/BH9 -> -0.0078166637 | BO9: =BN9*BL9 -> -0.00056178473 | BP9: =BM9*$L9 -> 127854.78 | BQ9: =BP9/$BP$19 -> 0.071537295 | BR9: 168.72 | BS9: =(BR9-BM9)/BM9 -> 0.0069829902 | BT9: =BS9*BQ9 -> 0.00049954422 | BU9: =BR9*$L9 -> 128747.59 | BV9: =BU9/$BU$19 -> 0.071914067 | BW9: 167.88 | BX9: =(BW9-BR9)/BR9 -> -0.0049786629 | BY9: =BX9*BV9 -> -0.00035803589 | BZ9: =BW9*$L9 -> 128106.6 | CA9: =BZ9/$BZ$19 -> 0.072131696 | CB9: 162.54 | CC9: =(CB9-BW9)/BW9 -> -0.031808435 | CD9: =CC9*CA9 -> -0.0022943963 | CE9: =CB9*$L9 -> 124031.73 | CF9: =CE9/$CE$19 -> 0.070982134 | CG9: 162.56 | CH9: =(CG9-CB9)/CB9 -> 0.00012304663 | CI9: =CH9*CF9 -> 8.7341127e-06 | CJ9: =CG9*$L9 -> 124046.99 | CK9: =CJ9/$CJ$19 -> 0.070112222 | CL9: 166.7 | CM9: =(CL9-CG9)/CG9 -> 0.02546752 | CN9: =CM9*CK9 -> 0.0017855844 | CO9: =CL9*$L9 -> 127206.16 | CP9: =CO9/$CO$19 -> 0.07198707 | CQ9: 166.54 | CR9: =(CQ9-CL9)/CL9 -> -0.00095980804 | CS9: =CR9*CP9 -> -6.9093769e-05 | CT9: =CQ9*$L9 -> 127084.07 | CU9: =CT9/$CT$19 -> 0.070846453 | CV9: 167 | CW9: =(CV9-CQ9)/CQ9 -> 0.0027620992 | CX9: =CW9*CW9 -> 7.629192e-06 | CY9: =CV9*$L9 -> 127435.08 | CZ9: =CY9/$CY$19 -> 0.071141025 | DA9: 165.18 | DB9: =(DA9-CV9)/CV9 -> -0.010898204 | DC9: =DB9*CZ9 -> -0.00077530937 | DD9: =DA9*$L9 -> 126046.27 | DE9: =DD9/$DD$19 -> 0.070605758 | DF9: 170.44 | DG9: =(DF9-DA9)/DA9 -> 0.031844049 | DH9: =DG9*DE9 -> 0.0022483732 | DI9: =DF9*$L9 -> 130060.09 | DJ9: =DI9/$DI$19 -> 0.070660617 | DK9: 166.45 | DL9: =(DK9-DF9)/DF9 -> -0.023409998 | DM9: =DL9*DJ9 -> -0.0016541649 | DN9: =DK9*$L9 -> 127015.39 | DO9: =DN9/$DN$19 -> 0.069728134 | DP9: 164.54 | DQ9: =(DP9-DK9)/DK9 -> -0.011474917 | DR9: =DQ9*DO9 -> -0.00080012457 | DS9: =DP9*$L9 -> 125557.9 | DT9: =DS9/$DS$19 -> 0.06946227 | DU9: 170.05 | DV9: =(DU9-DP9)/DP9 -> 0.033487298 | DW9: =DV9*DV9 -> 0.0011213991 | DX9: =DU9*$L9 -> 129762.49 | DY9: =DX9/$DX$19 -> 0.070407978 | DZ9: 171.3 | EA9: =(DZ9-DU9)/DU9 -> 0.0073507792 | EB9: =EA9*DY9 -> 0.0005175535 | EC9: =DZ9*$L9 -> 130716.35 | ED9: =EC9/$EC$19 -> 0.070510111 | EE9: 170.56 | EF9: =(EE9-DZ9)/DZ9 -> -0.0043199066 | EG9: =EF9*ED9 -> -0.00030459709 | EH9: =EE9*$L9 -> 130151.66 | EI9: =EH9/$EH$19 -> 0.070405958 | EJ9: 173.75 | EK9: =(EJ9-EE9)/EE9 -> 0.018703096 | EL9: =EK9*EI9 -> 0.0013168094 | EM9: =EJ9*$L9 -> 132585.9 | EN9: =EM9/$EM$19 -> 0.0704758 | EO9: 176.12 | EP9: =(EO9-EJ9)/EJ9 -> 0.013640288 | EQ9: =EP9*EN9 -> 0.0009613102 | ER9: =EO9*$L9 -> 134394.41 | ES9: =ER9/$ER$19 -> 0.07084472 | ET9: 175.76 | EU9: =(ET9-EO9)/EO9 -> -0.0020440609 | EV9: =EU9*EU9 -> 4.1781848e-06 | EW9: =ET9*$L9 -> 134119.7 | EX9: =EW9/$EW$19 -> 0.0711523 | EY9: 176.62 | EZ9: =(EY9-ET9)/ET9 -> 0.004893036 | FA9: =EZ9*EX9 -> 0.00034815076 | FB9: =EY9*$L9 -> 134775.96 | FC9: =FB9/$FB$19 -> 0.071150375 | FD9: 175.12 | FE9: =(FD9-EY9)/EY9 -> -0.0084928094 | FF9: =FE9*FC9 -> -0.00060426657 | FG9: =FD9*$L9 -> 133631.33 | FH9: =FG9/$FG$19 -> 0.071825741 | FI9: 174.83 | FJ9: =(FI9-FD9)/FD9 -> -0.0016560073 | FK9: =FJ9*FH9 -> -0.00011894395 | FL9: =FI9*$L9 -> 133410.03 | FM9: =FL9/$FL$19 -> 0.071288692 | FN9: 174.71 | FO9: =(FN9-FI9)/FI9 -> -0.00068638106 | FP9: =FO9*FM9 -> -4.8931207e-05 | FQ9: =FN9*$L9 -> 133318.46 | FR9: =FQ9/$FQ$19 -> 0.071019042 | FS9: 174.56 | FT9: =(FS9-FN9)/FN9 -> -0.00085856562 | FU9: =FT9*FR9 -> -6.0974508e-05 | FV9: =FS9*$L9 -> 133204 | FW9: =FV9/$FQ$19 -> 0.070958068 | FX9: 172.43 | FY9: =(FX9-FS9)/FS9 -> -0.012202108 | FZ9: =FY9*FW9 -> -0.00086583802 | GA9: =FX9*$L9 -> 131578.63 | GB9: =GA9/$GA$19 -> 0.071220477 | GC9: 174.88 | GD9: =(GC9-FX9)/FX9 -> 0.014208664 | GE9: =GD9*GB9 -> 0.0010119479 | GF9: =GC9*$L9 -> 133448.19 | GG9: =GF9/$GF$19 -> 0.071699026 | GH9: 174.35 | GI9: =(GH9-GC9)/GC9 -> -0.0030306496 | GJ9: =GI9*GG9 -> -0.00021729462 | GK9: =GH9*$L9 -> 133043.75 | GL9: =GK9/$GK$19 -> 0.071348078 | GM9: 163.09 | GN9: =(GM9-GH9)/GH9 -> -0.064582736 | GO9: =GN9*GN9 -> 0.0041709298 | GP9: =GM9*$L9 -> 124451.42 | GQ9: =GP9/$GP$19 -> 0.067702055 | GR9: 161.08 | GS9: =(GR9-GM9)/GM9 -> -0.012324483 | GT9: =GS9*GQ9 -> -0.00083439285 | GU9: =GR9*$L9 -> 122917.63 | GV9: =GU9/$GU$19 -> 0.067252073 | GW9: 161.08 | GX9: =(GW9-GR9)/GR9 -> 0 | GY9: =GX9*GV9 -> 0 | GZ9: =GW9*$L9 -> 122917.63 | HA9: =GZ9/$GZ$19 -> 0.06743973 | HB9: 154.39 | HC9: =(HB9-GW9)/GW9 -> -0.041532158 | HD9: =HC9*HA9 -> -0.0028009175 | HE9: =HB9*$L9 -> 117812.59 | HF9: =HE9/$GF$19 -> 0.063298334 | HG9: 157.26 | HH9: =(HG9-HB9)/HB9 -> 0.018589287 | HI9: =HH9*HF9 -> 0.0011766709 | HJ9: =HG9*$L9 -> 120002.64 | HK9: =HJ9/$HJ$19 -> 0.066571335 | HL9: 164.51 | HM9: =(HL9-HG9)/HG9 -> 0.046101997 | HN9: =HM9*HM9 -> 0.0021253941 | HO9: =HL9*$L9 -> 125535 | HP9: =HO9/$HO$19 -> 0.068179468
B10: 4 | C10: Punjab National Bank (PNB) | D10: PNB | E10: 109 | F10: 125687 | G10: =(F10/$F$19) -> 0.066595208 | H10: 7.06 | I10: 104.62 | J10: =(I10-E10)/E10 -> -0.040183486 | K10: =G10*J10 -> -0.0026760276 | L10: =F10/E10 -> 1153.0917 | M10: =L10*I10 -> 120636.46 | N10: =(M10/$M$19) -> 0.067404701 | O10: 102.78 | P10: =(O10-I10)/I10 -> -0.017587459 | Q10: =N10*P10 -> -0.0011854774 | R10: =O10*L10 -> 118514.77 | S10: =R10/$R$19 -> 0.066803247 | T10: 102.75 | U10: =(T10-O10)/O10 -> -0.00029188558 | V10: =U10*S10 -> -1.9498905e-05 | W10: =T10*$L10 -> 118480.18 | X10: =W10/$W$19 -> 0.066887408 | Y10: 104.62 | Z10: =(Y10-T10)/T10 -> 0.018199513 | AA10: =Z10*X10 -> 0.0012173183 | AB10: =Y10*$L10 -> 120636.46 | AC10: =AB10/$AB$19 -> 0.067327589 | AD10: 102.05 | AE10: =(AD10-Y10)/Y10 -> -0.024565093 | AF10: =AE10*AC10 -> -0.0016539085 | AG10: =AD10*$L10 -> 117673.01 | AH10: =AG10/$AG$19 -> 0.066799424 | AI10: 99.49 | AJ10: =(AI10-AD10)/AD10 -> -0.025085742 | AK10: =AJ10*AH10 -> -0.0016757131 | AL10: =AI10*$L10 -> 114721.1 | AM10: =AL10/$AL$19 -> 0.066486988 | AN10: 101.3 | AO10: =(AN10-AI10)/AI10 -> 0.018192783 | AP10: =AO10*AM10 -> 0.0012095834 | AQ10: =AN10*$L10 -> 116808.19 | AR10: =AQ10/$AQ$19 -> 0.066989979 | AS10: 102.22 | AT10: =(AS10-AN10)/AN10 -> 0.0090819348 | AU10: =AT10*AR10 -> 0.00060839862 | AV10: =AS10*$L10 -> 117869.04 | AW10: =AV10/$AV$19 -> 0.067549667 | AX10: 101.12 | AY10: =(AX10-AS10)/AS10 -> -0.010761104 | AZ10: =AY10*AW10 -> -0.00072690896 | BA10: =AX10*$L10 -> 116600.64 | BB10: =BA10/$BA$19 -> 0.06667266 | BC10: 102.66 | BD10: =(BC10-AX10)/AX10 -> 0.01522943 | BE10: =BD10*BB10 -> 0.0010153866 | BF10: =BC10*$L10 -> 118376.4 | BG10: =BF10/$BF$19 -> 0.067722186 | BH10: 106.26 | BI10: =(BH10-BC10)/BC10 -> 0.035067212 | BJ10: =BI10*BG10 -> 0.0023748283 | BK10: =BH10*$L10 -> 122527.53 | BL10: =BK10/$BK$19 -> 0.068337193 | BM10: 105.95 | BN10: =(BM10-BH10)/BH10 -> -0.0029173725 | BO10: =BN10*BL10 -> -0.00019936505 | BP10: =BM10*$L10 -> 122170.07 | BQ10: =BP10/$BP$19 -> 0.068356586 | BR10: 106.67 | BS10: =(BR10-BM10)/BM10 -> 0.0067956583 | BT10: =BS10*BQ10 -> 0.000464528 | BU10: =BR10*$L10 -> 123000.3 | BV10: =BU10/$BU$19 -> 0.068703822 | BW10: 106.05 | BX10: =(BW10-BR10)/BR10 -> -0.0058123184 | BY10: =BX10*BV10 -> -0.00039932849 | BZ10: =BW10*$L10 -> 122285.38 | CA10: =BZ10/$BZ$19 -> 0.068854001 | CB10: 103.78 | CC10: =(CB10-BW10)/BW10 -> -0.021404998 | CD10: =CC10*CA10 -> -0.0014738197 | CE10: =CB10*$L10 -> 119667.86 | CF10: =CE10/$CE$19 -> 0.068484736 | CG10: 104.09 | CH10: =(CG10-CB10)/CB10 -> 0.0029870881 | CI10: =CH10*CF10 -> 0.00020456994 | CJ10: =CG10*$L10 -> 120025.32 | CK10: =CJ10/$CJ$19 -> 0.067839146 | CL10: 105.9 | CM10: =(CL10-CG10)/CG10 -> 0.017388798 | CN10: =CM10*CK10 -> 0.0011796412 | CO10: =CL10*$L10 -> 122112.42 | CP10: =CO10/$CO$19 -> 0.069104477 | CQ10: 106.27 | CR10: =(CQ10-CL10)/CL10 -> 0.0034938621 | CS10: =CR10*CP10 -> 0.00024144151 | CT10: =CQ10*$L10 -> 122539.06 | CU10: =CT10/$CT$19 -> 0.068312717 | CV10: 106.85 | CW10: =(CV10-CQ10)/CQ10 -> 0.0054577962 | CX10: =CW10*CW10 -> 2.9787539e-05 | CY10: =CV10*$L10 -> 123207.85 | CZ10: =CY10/$CY$19 -> 0.06878116 | DA10: 105.71 | DB10: =(DA10-CV10)/CV10 -> -0.010669162 | DC10: =DB10*CZ10 -> -0.00073383736 | DD10: =DA10*$L10 -> 121893.33 | DE10: =DD10/$DD$19 -> 0.068279457 | DF10: 109.65 | DG10: =(DF10-DA10)/DA10 -> 0.037271781 | DH10: =DG10*DE10 -> 0.002544897 | DI10: =DF10*$L10 -> 126436.51 | DJ10: =DI10/$DI$19 -> 0.068691952 | DK10: 107.17 | DL10: =(DK10-DF10)/DF10 -> -0.022617419 | DM10: =DL10*DJ10 -> -0.0015536347 | DN10: =DK10*$L10 -> 123576.84 | DO10: =DN10/$DN$19 -> 0.067840462 | DP10: 106.17 | DQ10: =(DP10-DK10)/DK10 -> -0.0093309695 | DR10: =DQ10*DO10 -> -0.00063301728 | DS10: =DP10*$L10 -> 122423.75 | DT10: =DS10/$DS$19 -> 0.067728369 | DU10: 106.88 | DV10: =(DU10-DP10)/DP10 -> 0.0066873882 | DW10: =DV10*DV10 -> 4.472116e-05 | DX10: =DU10*$L10 -> 123242.45 | DY10: =DX10/$DX$19 -> 0.066870259 | DZ10: 107.96 | EA10: =(DZ10-DU10)/DU10 -> 0.01010479 | EB10: =EA10*DY10 -> 0.00067570995 | EC10: =DZ10*$L10 -> 124487.78 | ED10: =EC10/$EC$19 -> 0.067150343 | EE10: 107.97 | EF10: =(EE10-DZ10)/DZ10 -> 9.2626899e-05 | EG10: =EF10*ED10 -> 6.219928e-06 | EH10: =EE10*$L10 -> 124499.32 | EI10: =EH10/$EH$19 -> 0.067348301 | EJ10: 108.87 | EK10: =(EJ10-EE10)/EE10 -> 0.0083356488 | EL10: =EK10*EI10 -> 0.00056139179 | EM10: =EJ10*$L10 -> 125537.1 | EN10: =EM10/$EM$19 -> 0.06672902 | EO10: 109.58 | EP10: =(EO10-EJ10)/EJ10 -> 0.0065215395 | EQ10: =EP10*EN10 -> 0.00043517594 | ER10: =EO10*$L10 -> 126355.79 | ES10: =ER10/$ER$19 -> 0.066607239 | ET10: 108.77 | EU10: =(ET10-EO10)/EO10 -> -0.0073918598 | EV10: =EU10*EU10 -> 5.4639592e-05 | EW10: =ET10*$L10 -> 125421.79 | EX10: =EW10/$EW$19 -> 0.06653794 | EY10: 109.8 | EZ10: =(EY10-ET10)/ET10 -> 0.0094695228 | FA10: =EZ10*EX10 -> 0.00063008254 | FB10: =EY10*$L10 -> 126609.47 | FC10: =FB10/$FB$19 -> 0.066839159 | FD10: 107.43 | FE10: =(FD10-EY10)/EY10 -> -0.021584699 | FF10: =FE10*FC10 -> -0.0014427032 | FG10: =FD10*$L10 -> 123876.65 | FH10: =FG10/$FG$19 -> 0.066582679 | FI10: 107.71 | FJ10: =(FI10-FD10)/FD10 -> 0.0026063483 | FK10: =FJ10*FH10 -> 0.00017353765 | FL10: =FI10*$L10 -> 124199.51 | FM10: =FL10/$FL$19 -> 0.066366977 | FN10: 107.87 | FO10: =(FN10-FI10)/FI10 -> 0.0014854702 | FP10: =FO10*FM10 -> 9.8586169e-05 | FQ10: =FN10*$L10 -> 124384.01 | FR10: =FQ10/$FQ$19 -> 0.066259636 | FS10: 109.96 | FT10: =(FS10-FN10)/FN10 -> 0.019375174 | FU10: =FT10*FR10 -> 0.001283792 | FV10: =FS10*$L10 -> 126793.97 | FW10: =FV10/$FQ$19 -> 0.067543428 | FX10: 106.69 | FY10: =(FX10-FS10)/FS10 -> -0.029738087 | FZ10: =FY10*FW10 -> -0.0020086123 | GA10: =FX10*$L10 -> 123023.36 | GB10: =GA10/$GA$19 -> 0.066589705 | GC10: 107.54 | GD10: =(GC10-FX10)/FX10 -> 0.0079670072 | GE10: =GD10*GB10 -> 0.00053052066 | GF10: =GC10*$L10 -> 124003.49 | GG10: =GF10/$GF$19 -> 0.066624577 | GH10: 106.91 | GI10: =(GH10-GC10)/GC10 -> -0.0058582853 | GJ10: =GI10*GG10 -> -0.00039030578 | GK10: =GH10*$L10 -> 123277.04 | GL10: =GK10/$GK$19 -> 0.06611043 | GM10: 105.35 | GN10: =(GM10-GH10)/GH10 -> -0.014591713 | GO10: =GN10*GN10 -> 0.00021291808 | GP10: =GM10*$L10 -> 121478.22 | GQ10: =GP10/$GP$19 -> 0.066084618 | GR10: 104.29 | GS10: =(GR10-GM10)/GM10 -> -0.010061699 | GT10: =GS10*GQ10 -> -0.00066492354 | GU10: =GR10*$L10 -> 120255.94 | GV10: =GU10/$GU$19 -> 0.065795781 | GW10: 103.79 | GX10: =(GW10-GR10)/GR10 -> -0.0047943235 | GY10: =GX10*GV10 -> -0.00031544626 | GZ10: =GW10*$L10 -> 119679.39 | HA10: =GZ10/$GZ$19 -> 0.065663048 | HB10: 100.95 | HC10: =(HB10-GW10)/GW10 -> -0.027362944 | HD10: =HC10*HA10 -> -0.0017967343 | HE10: =HB10*$L10 -> 116404.61 | HF10: =HE10/$GF$19 -> 0.062541855 | HG10: 103.44 | HH10: =(HG10-HB10)/HB10 -> 0.024665676 | HI10: =HH10*HF10 -> 0.0015426371 | HJ10: =HG10*$L10 -> 119275.81 | HK10: =HJ10/$HJ$19 -> 0.066168125 | HL10: 105.41 | HM10: =(HL10-HG10)/HG10 -> 0.019044857 | HN10: =HM10*HM10 -> 0.00036270658 | HO10: =HL10*$L10 -> 121547.4 | HP10: =HO10/$HO$19 -> 0.066013756
B11: 5 | C11: Canara Bank | D11: CANBK | E11: 135 | F11: 122136 | G11: =(F11/$F$19) -> 0.064713712 | H11: 6.05 | I11: 129.43 | J11: =(I11-E11)/E11 -> -0.041259259 | K11: =G11*J11 -> -0.0026700398 | L11: =F11/E11 -> 904.71111 | M11: =L11*I11 -> 117096.76 | N11: =(M11/$M$19) -> 0.065426921 | O11: 130.01 | P11: =(O11-I11)/I11 -> 0.0044811867 | Q11: =N11*P11 -> 0.00029319025 | R11: =O11*L11 -> 117621.49 | S11: =R11/$R$19 -> 0.066299733 | T11: 129.26 | U11: =(T11-O11)/O11 -> -0.005768787 | V11: =U11*S11 -> -0.00038246904 | W11: =T11*$L11 -> 116942.96 | X11: =W11/$W$19 -> 0.066019579 | Y11: 130.84 | Z11: =(Y11-T11)/T11 -> 0.012223426 | AA11: =Z11*X11 -> 0.00080698542 | AB11: =Y11*$L11 -> 118372.4 | AC11: =AB11/$AB$19 -> 0.066064012 | AD11: 128.07 | AE11: =(AD11-Y11)/Y11 -> -0.021170896 | AF11: =AE11*AC11 -> -0.0013986343 | AG11: =AD11*$L11 -> 115866.35 | AH11: =AG11/$AG$19 -> 0.065773837 | AI11: 124.9 | AJ11: =(AI11-AD11)/AD11 -> -0.024752089 | AK11: =AJ11*AH11 -> -0.0016280399 | AL11: =AI11*$L11 -> 112998.42 | AM11: =AL11/$AL$19 -> 0.065488603 | AN11: 126.15 | AO11: =(AN11-AI11)/AI11 -> 0.010008006 | AP11: =AO11*AM11 -> 0.00065541036 | AQ11: =AN11*$L11 -> 114129.31 | AR11: =AQ11/$AQ$19 -> 0.065453626 | AS11: 127.66 | AT11: =(AS11-AN11)/AN11 -> 0.011969877 | AU11: =AT11*AR11 -> 0.00078347187 | AV11: =AS11*$L11 -> 115495.42 | AW11: =AV11/$AV$19 -> 0.066189369 | AX11: 127.97 | AY11: =(AX11-AS11)/AS11 -> 0.0024283252 | AZ11: =AY11*AW11 -> 0.00016072931 | BA11: =AX11*$L11 -> 115775.88 | BB11: =BA11/$BA$19 -> 0.066201061 | BC11: 128.23 | BD11: =(BC11-AX11)/AX11 -> 0.0020317262 | BE11: =BD11*BB11 -> 0.00013450243 | BF11: =BC11*$L11 -> 116011.11 | BG11: =BF11/$BF$19 -> 0.066369021 | BH11: 133.7 | BI11: =(BH11-BC11)/BC11 -> 0.042657724 | BJ11: =BI11*BG11 -> 0.0028311514 | BK11: =BH11*$L11 -> 120959.88 | BL11: =BK11/$BK$19 -> 0.067462867 | BM11: 133.15 | BN11: =(BM11-BH11)/BH11 -> -0.0041136874 | BO11: =BN11*BL11 -> -0.00027752114 | BP11: =BM11*$L11 -> 120462.28 | BQ11: =BP11/$BP$19 -> 0.067401046 | BR11: 134.16 | BS11: =(BR11-BM11)/BM11 -> 0.00758543 | BT11: =BS11*BQ11 -> 0.00051126591 | BU11: =BR11*$L11 -> 121376.04 | BV11: =BU11/$BU$19 -> 0.067796569 | BW11: 130.8 | BX11: =(BW11-BR11)/BR11 -> -0.025044723 | BY11: =BX11*BV11 -> -0.0016979463 | BZ11: =BW11*$L11 -> 118336.21 | CA11: =BZ11/$BZ$19 -> 0.066630383 | CB11: 127.96 | CC11: =(CB11-BW11)/BW11 -> -0.021712538 | CD11: =CC11*CA11 -> -0.0014467147 | CE11: =CB11*$L11 -> 115766.83 | CF11: =CE11/$CE$19 -> 0.066252216 | CG11: 129.08 | CH11: =(CG11-CB11)/CB11 -> 0.0087527352 | CI11: =CH11*CF11 -> 0.00057988811 | CJ11: =CG11*$L11 -> 116780.11 | CK11: =CJ11/$CJ$19 -> 0.066004931 | CL11: 131.85 | CM11: =(CL11-CG11)/CG11 -> 0.02145956 | CN11: =CM11*CK11 -> 0.0014164368 | CO11: =CL11*$L11 -> 119286.16 | CP11: =CO11/$CO$19 -> 0.067505074 | CQ11: 133.12 | CR11: =(CQ11-CL11)/CL11 -> 0.0096321578 | CS11: =CR11*CP11 -> 0.00065021952 | CT11: =CQ11*$L11 -> 120435.14 | CU11: =CT11/$CT$19 -> 0.067139831 | CV11: 135.81 | CW11: =(CV11-CQ11)/CQ11 -> 0.020207332 | CX11: =CW11*CW11 -> 0.00040833626 | CY11: =CV11*$L11 -> 122868.82 | CZ11: =CY11/$CY$19 -> 0.068591892 | DA11: 131.91 | DB11: =(DA11-CV11)/CV11 -> -0.028716589 | DC11: =DB11*CZ11 -> -0.0019697252 | DD11: =DA11*$L11 -> 119340.44 | DE11: =DD11/$DD$19 -> 0.066849439 | DF11: 137.51 | DG11: =(DF11-DA11)/DA11 -> 0.042453188 | DH11: =DG11*DE11 -> 0.0028379718 | DI11: =DF11*$L11 -> 124406.82 | DJ11: =DI11/$DI$19 -> 0.06758924 | DK11: 133.46 | DL11: =(DK11-DF11)/DF11 -> -0.029452403 | DM11: =DL11*DJ11 -> -0.0019906656 | DN11: =DK11*$L11 -> 120742.74 | DO11: =DN11/$DN$19 -> 0.066284616 | DP11: 131.52 | DQ11: =(DP11-DK11)/DK11 -> -0.014536191 | DR11: =DQ11*DO11 -> -0.00096352582 | DS11: =DP11*$L11 -> 118987.61 | DT11: =DS11/$DS$19 -> 0.065827394 | DU11: 131.67 | DV11: =(DU11-DP11)/DP11 -> 0.0011405109 | DW11: =DV11*DV11 -> 1.3007652e-06 | DX11: =DU11*$L11 -> 119123.31 | DY11: =DX11/$DX$19 -> 0.064635254 | DZ11: 132.2 | EA11: =(DZ11-DU11)/DU11 -> 0.0040252146 | EB11: =EA11*DY11 -> 0.00026017076 | EC11: =DZ11*$L11 -> 119602.81 | ED11: =EC11/$EC$19 -> 0.064515323 | EE11: 132.83 | EF11: =(EE11-DZ11)/DZ11 -> 0.0047655068 | EG11: =EF11*ED11 -> 0.00030744821 | EH11: =EE11*$L11 -> 120172.78 | EI11: =EH11/$EH$19 -> 0.065007847 | EJ11: 135.24 | EK11: =(EJ11-EE11)/EE11 -> 0.018143492 | EL11: =EK11*EI11 -> 0.0011794693 | EM11: =EJ11*$L11 -> 122353.13 | EN11: =EM11/$EM$19 -> 0.065036588 | EO11: 134.97 | EP11: =(EO11-EJ11)/EJ11 -> -0.0019964508 | EQ11: =EP11*EN11 -> -0.00012984235 | ER11: =EO11*$L11 -> 122108.86 | ES11: =ER11/$ER$19 -> 0.064368508 | ET11: 133.74 | EU11: =(ET11-EO11)/EO11 -> -0.0091131363 | EV11: =EU11*EU11 -> 8.3049252e-05 | EW11: =ET11*$L11 -> 120996.06 | EX11: =EW11/$EW$19 -> 0.064190034 | EY11: 134.82 | EZ11: =(EY11-ET11)/ET11 -> 0.0080753701 | FA11: =EZ11*EX11 -> 0.00051835828 | FB11: =EY11*$L11 -> 121973.15 | FC11: =FB11/$FB$19 -> 0.064391571 | FD11: 130.37 | FE11: =(FD11-EY11)/EY11 -> -0.033006972 | FF11: =FE11*FC11 -> -0.0021253708 | FG11: =FD11*$L11 -> 117947.19 | FH11: =FG11/$FG$19 -> 0.063395644 | FI11: 130.15 | FJ11: =(FI11-FD11)/FD11 -> -0.0016875048 | FK11: =FJ11*FH11 -> -0.00010698045 | FL11: =FI11*$L11 -> 117748.15 | FM11: =FL11/$FL$19 -> 0.062919642 | FN11: 128.95 | FO11: =(FN11-FI11)/FI11 -> -0.0092201306 | FP11: =FO11*FM11 -> -0.00058012732 | FQ11: =FN11*$L11 -> 116662.5 | FR11: =FQ11/$FQ$19 -> 0.062146372 | FS11: 125.86 | FT11: =(FS11-FN11)/FN11 -> -0.023962776 | FU11: =FT11*FR11 -> -0.0014891996 | FV11: =FS11*$L11 -> 113866.94 | FW11: =FV11/$FQ$19 -> 0.060657172 | FX11: 125.52 | FY11: =(FX11-FS11)/FS11 -> -0.0027014143 | FZ11: =FY11*FW11 -> -0.00016386015 | GA11: =FX11*$L11 -> 113559.34 | GB11: =GA11/$GA$19 -> 0.061467049 | GC11: 126.28 | GD11: =(GC11-FX11)/FX11 -> 0.006054812 | GE11: =GD11*GB11 -> 0.00037217143 | GF11: =GC11*$L11 -> 114246.92 | GG11: =GF11/$GF$19 -> 0.06138257 | GH11: 126.64 | GI11: =(GH11-GC11)/GC11 -> 0.0028508077 | GJ11: =GI11*GG11 -> 0.0001749899 | GK11: =GH11*$L11 -> 114572.62 | GL11: =GK11/$GK$19 -> 0.061442462 | GM11: 127.19 | GN11: =(GM11-GH11)/GH11 -> 0.0043430196 | GO11: =GN11*GN11 -> 1.8861819e-05 | GP11: =GM11*$L11 -> 115070.21 | GQ11: =GP11/$GP$19 -> 0.062598636 | GR11: 126.46 | GS11: =(GR11-GM11)/GM11 -> -0.0057394449 | GT11: =GS11*GQ11 -> -0.00035928142 | GU11: =GR11*$L11 -> 114409.77 | GV11: =GU11/$GU$19 -> 0.062597158 | GW11: 125.03 | GX11: =(GW11-GR11)/GR11 -> -0.011307923 | GY11: =GX11*GV11 -> -0.00070784387 | GZ11: =GW11*$L11 -> 113116.03 | HA11: =GZ11/$GZ$19 -> 0.062062008 | HB11: 121.15 | HC11: =(HB11-GW11)/GW11 -> -0.031032552 | HD11: =HC11*HA11 -> -0.0019259425 | HE11: =HB11*$L11 -> 109605.75 | HF11: =HE11/$GF$19 -> 0.058888964 | HG11: 124.8 | HH11: =(HG11-HB11)/HB11 -> 0.030127941 | HI11: =HH11*HF11 -> 0.0017742032 | HJ11: =HG11*$L11 -> 112907.95 | HK11: =HJ11/$HJ$19 -> 0.06263556 | HL11: 129.3 | HM11: =(HL11-HG11)/HG11 -> 0.036057692 | HN11: =HM11*HM11 -> 0.0013001572 | HO11: =HL11*$L11 -> 116979.15 | HP11: =HO11/$HO$19 -> 0.063532686
B12: 6 | C12: Indian Bank | D12: INDIANB | E12: 852 | F12: 114741 | G12: =(F12/$F$19) -> 0.060795474 | H12: 9.36 | I12: 839.65 | J12: =(I12-E12)/E12 -> -0.014495305 | K12: =G12*J12 -> -0.00088124895 | L12: =F12/E12 -> 134.67254 | M12: =L12*I12 -> 113077.79 | N12: =(M12/$M$19) -> 0.063181355 | O12: 821.4 | P12: =(O12-I12)/I12 -> -0.021735247 | Q12: =N12*P12 -> -0.0013732624 | R12: =O12*L12 -> 110620.02 | S12: =R12/$R$19 -> 0.062353212 | T12: 813.95 | U12: =(T12-O12)/O12 -> -0.0090698807 | V12: =U12*S12 -> -0.0005655362 | W12: =T12*$L12 -> 109616.71 | X12: =W12/$W$19 -> 0.061883581 | Y12: 831.75 | Z12: =(Y12-T12)/T12 -> 0.021868665 | AA12: =Z12*X12 -> 0.0013533113 | AB12: =Y12*$L12 -> 112013.88 | AC12: =AB12/$AB$19 -> 0.062515302 | AD12: 820.6 | AE12: =(AD12-Y12)/Y12 -> -0.01340547 | AF12: =AE12*AC12 -> -0.00083804703 | AG12: =AD12*$L12 -> 110512.28 | AH12: =AG12/$AG$19 -> 0.062734493 | AI12: 810 | AJ12: =(AI12-AD12)/AD12 -> -0.012917378 | AK12: =AJ12*AH12 -> -0.00081036513 | AL12: =AI12*$L12 -> 109084.75 | AM12: =AL12/$AL$19 -> 0.063220426 | AN12: 817.1 | AO12: =(AN12-AI12)/AI12 -> 0.0087654321 | AP12: =AO12*AM12 -> 0.00055415435 | AQ12: =AN12*$L12 -> 110040.93 | AR12: =AQ12/$AQ$19 -> 0.063108925 | AS12: 810.2 | AT12: =(AS12-AN12)/AN12 -> -0.0084444988 | AU12: =AT12*AR12 -> -0.00053292324 | AV12: =AS12*$L12 -> 109111.69 | AW12: =AV12/$AV$19 -> 0.06253091 | AX12: 818.95 | AY12: =(AX12-AS12)/AS12 -> 0.010799803 | AZ12: =AY12*AW12 -> 0.00067532148 | BA12: =AX12*$L12 -> 110290.07 | BB12: =BA12/$BA$19 -> 0.063064257 | BC12: 825.95 | BD12: =(BC12-AX12)/AX12 -> 0.0085475304 | BE12: =BD12*BB12 -> 0.00053904365 | BF12: =BC12*$L12 -> 111232.78 | BG12: =BF12/$BF$19 -> 0.06363538 | BH12: 840.15 | BI12: =(BH12-BC12)/BC12 -> 0.017192324 | BJ12: =BI12*BG12 -> 0.0010940401 | BK12: =BH12*$L12 -> 113145.13 | BL12: =BK12/$BK$19 -> 0.063104355 | BM12: 835.5 | BN12: =(BM12-BH12)/BH12 -> -0.0055347259 | BO12: =BN12*BL12 -> -0.00034926531 | BP12: =BM12*$L12 -> 112518.9 | BQ12: =BP12/$BP$19 -> 0.062956566 | BR12: 833.35 | BS12: =(BR12-BM12)/BM12 -> -0.0025733094 | BT12: =BS12*BQ12 -> -0.00016200672 | BU12: =BR12*$L12 -> 112229.36 | BV12: =BU12/$BU$19 -> 0.062687539 | BW12: 833 | BX12: =(BW12-BR12)/BR12 -> -0.0004199916 | BY12: =BX12*BV12 -> -2.632824e-05 | BZ12: =BW12*$L12 -> 112182.22 | CA12: =BZ12/$BZ$19 -> 0.063165317 | CB12: 809.75 | CC12: =(CB12-BW12)/BW12 -> -0.027911164 | CD12: =CC12*CA12 -> -0.0017630176 | CE12: =CB12*$L12 -> 109051.09 | CF12: =CE12/$CE$19 -> 0.06240886 | CG12: 878.3 | CH12: =(CG12-CB12)/CB12 -> 0.084655758 | CI12: =CH12*CF12 -> 0.0052832693 | CJ12: =CG12*$L12 -> 118282.89 | CK12: =CJ12/$CJ$19 -> 0.066854312 | CL12: 847.9 | CM12: =(CL12-CG12)/CG12 -> -0.034612319 | CN12: =CM12*CK12 -> -0.0023139828 | CO12: =CL12*$L12 -> 114188.84 | CP12: =CO12/$CO$19 -> 0.064620458 | CQ12: 848.25 | CR12: =(CQ12-CL12)/CL12 -> 0.00041278453 | CS12: =CR12*CP12 -> 2.6674325e-05 | CT12: =CQ12*$L12 -> 114235.98 | CU12: =CT12/$CT$19 -> 0.063683939 | CV12: 842.05 | CW12: =(CV12-CQ12)/CQ12 -> -0.0073091659 | CX12: =CW12*CW12 -> 5.3423907e-05 | CY12: =CV12*$L12 -> 113401.01 | CZ12: =CY12/$CY$19 -> 0.063306459 | DA12: 843 | DB12: =(DA12-CV12)/CV12 -> 0.001128199 | DC12: =DB12*CZ12 -> 7.1422286e-05 | DD12: =DA12*$L12 -> 113528.95 | DE12: =DD12/$DD$19 -> 0.063594086 | DF12: 874.95 | DG12: =(DF12-DA12)/DA12 -> 0.037900356 | DH12: =DG12*DE12 -> 0.0024102385 | DI12: =DF12*$L12 -> 117831.73 | DJ12: =DI12/$DI$19 -> 0.064017046 | DK12: 833.45 | DL12: =(DK12-DF12)/DF12 -> -0.047431282 | DM12: =DL12*DJ12 -> -0.0030364106 | DN12: =DK12*$L12 -> 112242.82 | DO12: =DN12/$DN$19 -> 0.061618382 | DP12: 825.65 | DQ12: =(DP12-DK12)/DK12 -> -0.0093586898 | DR12: =DQ12*DO12 -> -0.00057666732 | DS12: =DP12*$L12 -> 111192.38 | DT12: =DS12/$DS$19 -> 0.061514849 | DU12: 845.5 | DV12: =(DU12-DP12)/DP12 -> 0.024041664 | DW12: =DV12*DV12 -> 0.00057800161 | DX12: =DU12*$L12 -> 113865.63 | DY12: =DX12/$DX$19 -> 0.061782481 | DZ12: 849.6 | EA12: =(DZ12-DU12)/DU12 -> 0.0048492017 | EB12: =EA12*DY12 -> 0.00029959571 | EC12: =DZ12*$L12 -> 114417.79 | ED12: =EC12/$EC$19 -> 0.061718453 | EE12: 853.3 | EF12: =(EE12-DZ12)/DZ12 -> 0.0043549906 | EG12: =EF12*ED12 -> 0.00026878328 | EH12: =EE12*$L12 -> 114916.07 | EI12: =EH12/$EH$19 -> 0.062164217 | EJ12: 876.35 | EK12: =(EJ12-EE12)/EE12 -> 0.027012774 | EL12: =EK12*EI12 -> 0.0016792279 | EM12: =EJ12*$L12 -> 118020.28 | EN12: =EM12/$EM$19 -> 0.062733467 | EO12: 875.7 | EP12: =(EO12-EJ12)/EJ12 -> -0.00074171279 | EQ12: =EP12*EN12 -> -4.6530215e-05 | ER12: =EO12*$L12 -> 117932.74 | ES12: =ER12/$ER$19 -> 0.062167107 | ET12: 870.65 | EU12: =(ET12-EO12)/EO12 -> -0.0057668151 | EV12: =EU12*EU12 -> 3.3256157e-05 | EW12: =ET12*$L12 -> 117252.64 | EX12: =EW12/$EW$19 -> 0.062204099 | EY12: 861.1 | EZ12: =(EY12-ET12)/ET12 -> -0.010968816 | FA12: =EZ12*EX12 -> -0.00068230534 | FB12: =EY12*$L12 -> 115966.52 | FC12: =FB12/$FB$19 -> 0.061220574 | FD12: 846.4 | FE12: =(FD12-EY12)/EY12 -> -0.017071188 | FF12: =FE12*FC12 -> -0.0010451079 | FG12: =FD12*$L12 -> 113986.83 | FH12: =FG12/$FG$19 -> 0.061266987 | FI12: 843.65 | FJ12: =(FI12-FD12)/FD12 -> -0.0032490548 | FK12: =FJ12*FH12 -> -0.0001990598 | FL12: =FI12*$L12 -> 113616.48 | FM12: =FL12/$FL$19 -> 0.060711854 | FN12: 832.6 | FO12: =(FN12-FI12)/FI12 -> -0.013097849 | FP12: =FO12*FM12 -> -0.00079519467 | FQ12: =FN12*$L12 -> 112128.35 | FR12: =FQ12/$FQ$19 -> 0.059731023 | FS12: 814.7 | FT12: =(FS12-FN12)/FN12 -> -0.021498919 | FU12: =FT12*FR12 -> -0.0012841524 | FV12: =FS12*$L12 -> 109717.71 | FW12: =FV12/$FQ$19 -> 0.05844687 | FX12: 816.65 | FY12: =(FX12-FS12)/FS12 -> 0.0023935191 | FZ12: =FY12*FW12 -> 0.0001398937 | GA12: =FX12*$L12 -> 109980.33 | GB12: =GA12/$GA$19 -> 0.059529812 | GC12: 820.95 | GD12: =(GC12-FX12)/FX12 -> 0.0052654136 | GE12: =GD12*GB12 -> 0.00031344908 | GF12: =GC12*$L12 -> 110559.42 | GG12: =GF12/$GF$19 -> 0.05940135 | GH12: 815.1 | GI12: =(GH12-GC12)/GC12 -> -0.0071258907 | GJ12: =GI12*GG12 -> -0.00042328753 | GK12: =GH12*$L12 -> 109771.58 | GL12: =GK12/$GK$19 -> 0.058867788 | GM12: 798.95 | GN12: =(GM12-GH12)/GH12 -> -0.01981352 | GO12: =GN12*GN12 -> 0.00039257557 | GP12: =GM12*$L12 -> 107596.62 | GQ12: =GP12/$GP$19 -> 0.058532977 | GR12: 786.9 | GS12: =(GR12-GM12)/GM12 -> -0.015082296 | GT12: =GS12*GQ12 -> -0.00088281166 | GU12: =GR12*$L12 -> 105973.82 | GV12: =GU12/$GU$19 -> 0.057981587 | GW12: 785.95 | GX12: =(GW12-GR12)/GR12 -> -0.001207269 | GY12: =GX12*GV12 -> -6.9999374e-05 | GZ12: =GW12*$L12 -> 105845.88 | HA12: =GZ12/$GZ$19 -> 0.058073181 | HB12: 772.4 | HC12: =(HB12-GW12)/GW12 -> -0.017240282 | HD12: =HC12*HA12 -> -0.0010011981 | HE12: =HB12*$L12 -> 104021.07 | HF12: =HE12/$GF$19 -> 0.055888425 | HG12: 793.15 | HH12: =(HG12-HB12)/HB12 -> 0.026864319 | HI12: =HH12*HF12 -> 0.0015014045 | HJ12: =HG12*$L12 -> 106815.52 | HK12: =HJ12/$HJ$19 -> 0.059255794 | HL12: 870.7 | HM12: =(HL12-HG12)/HG12 -> 0.097774696 | HN12: =HM12*HM12 -> 0.0095598911 | HO12: =HL12*$L12 -> 117259.38 | HP12: =HO12/$HO$19 -> 0.063684882
B13: 7 | C13: Bank of India (BOI) | D13: BANKINDIA | E13: 140 | F13: 63678 | G13: =(F13/$F$19) -> 0.033739763 | H13: 6.25 | I13: 143.86 | J13: =(I13-E13)/E13 -> 0.027571429 | K13: =G13*J13 -> 0.00093025347 | L13: =F13/E13 -> 454.84286 | M13: =L13*I13 -> 65433.693 | N13: =(M13/$M$19) -> 0.036560577 | O13: 140.14 | P13: =(O13-I13)/I13 -> -0.025858474 | Q13: =N13*P13 -> -0.00094540072 | R13: =O13*L13 -> 63741.678 | S13: =R13/$R$19 -> 0.035929286 | T13: 140.59 | U13: =(T13-O13)/O13 -> 0.0032110746 | V13: =U13*S13 -> 0.00011537162 | W13: =T13*$L13 -> 63946.357 | X13: =W13/$W$19 -> 0.036100605 | Y13: 143.95 | Z13: =(Y13-T13)/T13 -> 0.023899282 | AA13: =Z13*X13 -> 0.00086277854 | AB13: =Y13*$L13 -> 65474.629 | AC13: =AB13/$AB$19 -> 0.036541598 | AD13: 142.26 | AE13: =(AD13-Y13)/Y13 -> -0.011740188 | AF13: =AE13*AC13 -> -0.00042900521 | AG13: =AD13*$L13 -> 64705.945 | AH13: =AG13/$AG$19 -> 0.036731615 | AI13: 138.22 | AJ13: =(AI13-AD13)/AD13 -> -0.028398707 | AK13: =AJ13*AH13 -> -0.0010431304 | AL13: =AI13*$L13 -> 62868.38 | AM13: =AL13/$AL$19 -> 0.036435575 | AN13: 138.64 | AO13: =(AN13-AI13)/AI13 -> 0.0030386341 | AP13: =AO13*AM13 -> 0.00011071438 | AQ13: =AN13*$L13 -> 63059.414 | AR13: =AQ13/$AQ$19 -> 0.036164833 | AS13: 139.2 | AT13: =(AS13-AN13)/AN13 -> 0.0040392383 | AU13: =AT13*AR13 -> 0.00014607838 | AV13: =AS13*$L13 -> 63314.126 | AW13: =AV13/$AV$19 -> 0.036284746 | AX13: 139.23 | AY13: =(AX13-AS13)/AS13 -> 0.00021551724 | AZ13: =AY13*AW13 -> 7.8199884e-06 | BA13: =AX13*$L13 -> 63327.771 | BB13: =BA13/$BA$19 -> 0.036211045 | BC13: 139.92 | BD13: =(BC13-AX13)/AX13 -> 0.0049558285 | BE13: =BD13*BB13 -> 0.00017945573 | BF13: =BC13*$L13 -> 63641.613 | BG13: =BF13/$BF$19 -> 0.036408855 | BH13: 146.01 | BI13: =(BH13-BC13)/BC13 -> 0.043524871 | BJ13: =BI13*BG13 -> 0.0015846907 | BK13: =BH13*$L13 -> 66411.606 | BL13: =BK13/$BK$19 -> 0.037039698 | BM13: 145.05 | BN13: =(BM13-BH13)/BH13 -> -0.0065748921 | BO13: =BN13*BL13 -> -0.00024353202 | BP13: =BM13*$L13 -> 65974.956 | BQ13: =BP13/$BP$19 -> 0.036914301 | BR13: 147 | BS13: =(BR13-BM13)/BM13 -> 0.01344364 | BT13: =BS13*BQ13 -> 0.00049626258 | BU13: =BR13*$L13 -> 66861.9 | BV13: =BU13/$BU$19 -> 0.037346805 | BW13: 139.91 | BX13: =(BW13-BR13)/BR13 -> -0.048231293 | BY13: =BX13*BV13 -> -0.0018012847 | BZ13: =BW13*$L13 -> 63637.064 | CA13: =BZ13/$BZ$19 -> 0.035831483 | CB13: 136.74 | CC13: =(CB13-BW13)/BW13 -> -0.022657423 | CD13: =CC13*CA13 -> -0.00081184905 | CE13: =CB13*$L13 -> 62195.212 | CF13: =CE13/$CE$19 -> 0.035593706 | CG13: 137.29 | CH13: =(CG13-CB13)/CB13 -> 0.004022232 | CI13: =CH13*CF13 -> 0.00014316614 | CJ13: =CG13*$L13 -> 62445.376 | CK13: =CJ13/$CJ$19 -> 0.035294561 | CL13: 139.69 | CM13: =(CL13-CG13)/CG13 -> 0.017481244 | CN13: =CM13*CK13 -> 0.00061699284 | CO13: =CL13*$L13 -> 63536.999 | CP13: =CO13/$CO$19 -> 0.035956139 | CQ13: 141.46 | CR13: =(CQ13-CL13)/CL13 -> 0.012670914 | CS13: =CR13*CP13 -> 0.00045559716 | CT13: =CQ13*$L13 -> 64342.071 | CU13: =CT13/$CT$19 -> 0.035869229 | CV13: 141.46 | CW13: =(CV13-CQ13)/CQ13 -> 0 | CX13: =CW13*CW13 -> 0 | CY13: =CV13*$L13 -> 64342.071 | CZ13: =CY13/$CY$19 -> 0.035919157 | DA13: 140.08 | DB13: =(DA13-CV13)/CV13 -> -0.0097554079 | DC13: =DB13*CZ13 -> -0.00035040603 | DD13: =DA13*$L13 -> 63714.387 | DE13: =DD13/$DD$19 -> 0.035690089 | DF13: 147.72 | DG13: =(DF13-DA13)/DA13 -> 0.054540263 | DH13: =DG13*DE13 -> 0.0019465468 | DI13: =DF13*$L13 -> 67189.387 | DJ13: =DI13/$DI$19 -> 0.036503461 | DK13: 144.86 | DL13: =(DK13-DF13)/DF13 -> -0.019360953 | DM13: =DL13*DJ13 -> -0.00070674179 | DN13: =DK13*$L13 -> 65888.536 | DO13: =DN13/$DN$19 -> 0.036171087 | DP13: 141.73 | DQ13: =(DP13-DK13)/DK13 -> -0.021607069 | DR13: =DQ13*DO13 -> -0.00078155117 | DS13: =DP13*$L13 -> 64464.878 | DT13: =DS13/$DS$19 -> 0.03566384 | DU13: 145.68 | DV13: =(DU13-DP13)/DP13 -> 0.027869893 | DW13: =DV13*DV13 -> 0.00077673096 | DX13: =DU13*$L13 -> 66261.507 | DY13: =DX13/$DX$19 -> 0.035952907 | DZ13: 146.23 | EA13: =(DZ13-DU13)/DU13 -> 0.0037753981 | EB13: =EA13*DY13 -> 0.00013573654 | EC13: =DZ13*$L13 -> 66511.671 | ED13: =EC13/$EC$19 -> 0.035877267 | EE13: 145.67 | EF13: =(EE13-DZ13)/DZ13 -> -0.0038295835 | EG13: =EF13*ED13 -> -0.00013739499 | EH13: =EE13*$L13 -> 66256.959 | EI13: =EH13/$EH$19 -> 0.035841913 | EJ13: 147.14 | EK13: =(EJ13-EE13)/EE13 -> 0.010091302 | EL13: =EK13*EI13 -> 0.00036169158 | EM13: =EJ13*$L13 -> 66925.578 | EN13: =EM13/$EM$19 -> 0.035574172 | EO13: 147.67 | EP13: =(EO13-EJ13)/EJ13 -> 0.0036020117 | EQ13: =EP13*EN13 -> 0.00012813858 | ER13: =EO13*$L13 -> 67166.645 | ES13: =ER13/$ER$19 -> 0.03540625 | ET13: 146.57 | EU13: =(ET13-EO13)/EO13 -> -0.0074490418 | EV13: =EU13*EU13 -> 5.5488223e-05 | EW13: =ET13*$L13 -> 66666.318 | EX13: =EW13/$EW$19 -> 0.035367375 | EY13: 146.09 | EZ13: =(EY13-ET13)/ET13 -> -0.0032748857 | FA13: =EZ13*EX13 -> -0.00011582411 | FB13: =EY13*$L13 -> 66447.993 | FC13: =FB13/$FB$19 -> 0.035078954 | FD13: 144.51 | FE13: =(FD13-EY13)/EY13 -> -0.010815251 | FF13: =FE13*FC13 -> -0.00037938769 | FG13: =FD13*$L13 -> 65729.341 | FH13: =FG13/$FG$19 -> 0.035328981 | FI13: 144.15 | FJ13: =(FI13-FD13)/FD13 -> -0.0024911771 | FK13: =FJ13*FH13 -> -8.8010747e-05 | FL13: =FI13*$L13 -> 65565.598 | FM13: =FL13/$FL$19 -> 0.035035488 | FN13: 144.72 | FO13: =(FN13-FI13)/FI13 -> 0.0039542144 | FP13: =FO13*FM13 -> 0.00013853783 | FQ13: =FN13*$L13 -> 65824.858 | FR13: =FQ13/$FQ$19 -> 0.035065048 | FS13: 142.55 | FT13: =(FS13-FN13)/FN13 -> -0.014994472 | FU13: =FT13*FR13 -> -0.00052578189 | FV13: =FS13*$L13 -> 64837.849 | FW13: =FV13/$FQ$19 -> 0.034539266 | FX13: 140.39 | FY13: =(FX13-FS13)/FS13 -> -0.015152578 | FZ13: =FY13*FW13 -> -0.00052335893 | GA13: =FX13*$L13 -> 63855.389 | GB13: =GA13/$GA$19 -> 0.034563448 | GC13: 141.63 | GD13: =(GC13-FX13)/FX13 -> 0.0088325379 | GE13: =GD13*GB13 -> 0.00030528297 | GF13: =GC13*$L13 -> 64419.394 | GG13: =GF13/$GF$19 -> 0.034611244 | GH13: 144.96 | GI13: =(GH13-GC13)/GC13 -> 0.023511968 | GJ13: =GI13*GG13 -> 0.00081377844 | GK13: =GH13*$L13 -> 65934.021 | GL13: =GK13/$GK$19 -> 0.035358786 | GM13: 144.05 | GN13: =(GM13-GH13)/GH13 -> -0.0062775938 | GO13: =GN13*GN13 -> 3.9408184e-05 | GP13: =GM13*$L13 -> 65520.114 | GQ13: =GP13/$GP$19 -> 0.035643195 | GR13: 139.8 | GS13: =(GR13-GM13)/GM13 -> -0.029503645 | GT13: =GS13*GQ13 -> -0.0010516041 | GU13: =GR13*$L13 -> 63587.031 | GV13: =GU13/$GU$19 -> 0.034790451 | GW13: 142.41 | GX13: =(GW13-GR13)/GR13 -> 0.018669528 | GY13: =GX13*GV13 -> 0.0006495213 | GZ13: =GW13*$L13 -> 64774.171 | HA13: =GZ13/$GZ$19 -> 0.035538863 | HB13: 135.12 | HC13: =(HB13-GW13)/GW13 -> -0.051190225 | HD13: =HC13*HA13 -> -0.0018192424 | HE13: =HB13*$L13 -> 61458.367 | HF13: =HE13/$GF$19 -> 0.033020343 | HG13: 138.53 | HH13: =(HG13-HB13)/HB13 -> 0.025236827 | HI13: =HH13*HF13 -> 0.00083332868 | HJ13: =HG13*$L13 -> 63009.381 | HK13: =HJ13/$HJ$19 -> 0.034954385 | HL13: 144.9 | HM13: =(HL13-HG13)/HG13 -> 0.04598282 | HN13: =HM13*HM13 -> 0.0021144197 | HO13: =HL13*$L13 -> 65906.73 | HP13: =HO13/$HO$19 -> 0.035794684
B14: 8 | C14: Indian Overseas Bank (IOB) | D14: IOB | E14: 35 | F14: 67398 | G14: =(F14/$F$19) -> 0.035710804 | H14: 12.9 | I14: 34.29 | J14: =(I14-E14)/E14 -> -0.020285714 | K14: =G14*J14 -> -0.00072441916 | L14: =F14/E14 -> 1925.6571 | M14: =L14*I14 -> 66030.783 | N14: =(M14/$M$19) -> 0.036894197 | O14: 33.65 | P14: =(O14-I14)/I14 -> -0.018664334 | Q14: =N14*P14 -> -0.0006886056 | R14: =O14*L14 -> 64798.363 | S14: =R14/$R$19 -> 0.036524908 | T14: 33.68 | U14: =(T14-O14)/O14 -> 0.00089153046 | V14: =U14*S14 -> 3.2563068e-05 | W14: =T14*$L14 -> 64856.133 | X14: =W14/$W$19 -> 0.036614215 | Y14: 33.82 | Z14: =(Y14-T14)/T14 -> 0.0041567696 | AA14: =Z14*X14 -> 0.00015219685 | AB14: =Y14*$L14 -> 65125.725 | AC14: =AB14/$AB$19 -> 0.036346873 | AD14: 33.79 | AE14: =(AD14-Y14)/Y14 -> -0.00088704908 | AF14: =AE14*AC14 -> -3.2241461e-05 | AG14: =AD14*$L14 -> 65067.955 | AH14: =AG14/$AG$19 -> 0.036937118 | AI14: 33.43 | AJ14: =(AI14-AD14)/AD14 -> -0.01065404 | AK14: =AJ14*AH14 -> -0.00039352952 | AL14: =AI14*$L14 -> 64374.718 | AM14: =AL14/$AL$19 -> 0.037308579 | AN14: 33.54 | AO14: =(AN14-AI14)/AI14 -> 0.0032904577 | AP14: =AO14*AM14 -> 0.0001227623 | AQ14: =AN14*$L14 -> 64586.541 | AR14: =AQ14/$AQ$19 -> 0.037040646 | AS14: 33.49 | AT14: =(AS14-AN14)/AN14 -> -0.0014907573 | AU14: =AT14*AR14 -> -5.5218614e-05 | AV14: =AS14*$L14 -> 64490.258 | AW14: =AV14/$AV$19 -> 0.036958777 | AX14: 33.77 | AY14: =(AX14-AS14)/AS14 -> 0.0083607047 | AZ14: =AY14*AW14 -> 0.00030900142 | BA14: =AX14*$L14 -> 65029.442 | BB14: =BA14/$BA$19 -> 0.037184067 | BC14: 33.43 | BD14: =(BC14-AX14)/AX14 -> -0.010068108 | BE14: =BD14*BB14 -> -0.00037437319 | BF14: =BC14*$L14 -> 64374.718 | BG14: =BF14/$BF$19 -> 0.036828259 | BH14: 33.79 | BI14: =(BH14-BC14)/BC14 -> 0.010768771 | BJ14: =BI14*BG14 -> 0.00039659507 | BK14: =BH14*$L14 -> 65067.955 | BL14: =BK14/$BK$19 -> 0.036290305 | BM14: 33.71 | BN14: =(BM14-BH14)/BH14 -> -0.0023675644 | BO14: =BN14*BL14 -> -8.5919633e-05 | BP14: =BM14*$L14 -> 64913.902 | BQ14: =BP14/$BP$19 -> 0.03632062 | BR14: 33.88 | BS14: =(BR14-BM14)/BM14 -> 0.0050430139 | BT14: =BS14*BQ14 -> 0.0001831654 | BU14: =BR14*$L14 -> 65241.264 | BV14: =BU14/$BU$19 -> 0.036441573 | BW14: 33.42 | BX14: =(BW14-BR14)/BR14 -> -0.013577332 | BY14: =BX14*BV14 -> -0.00049477932 | BZ14: =BW14*$L14 -> 64355.462 | CA14: =BZ14/$BZ$19 -> 0.036235984 | CB14: 32.95 | CC14: =(CB14-BW14)/BW14 -> -0.014063435 | CD14: =CC14*CA14 -> -0.0005096024 | CE14: =CB14*$L14 -> 63450.403 | CF14: =CE14/$CE$19 -> 0.036312039 | CG14: 32.79 | CH14: =(CG14-CB14)/CB14 -> -0.0048558422 | CI14: =CH14*CF14 -> -0.00017632553 | CJ14: =CG14*$L14 -> 63142.298 | CK14: =CJ14/$CJ$19 -> 0.035688466 | CL14: 33.01 | CM14: =(CL14-CG14)/CG14 -> 0.0067093626 | CN14: =CM14*CK14 -> 0.00023944686 | CO14: =CL14*$L14 -> 63565.942 | CP14: =CO14/$CO$19 -> 0.035972519 | CQ14: 32.92 | CR14: =(CQ14-CL14)/CL14 -> -0.0027264465 | CS14: =CR14*CP14 -> -9.8077149e-05 | CT14: =CQ14*$L14 -> 63392.633 | CU14: =CT14/$CT$19 -> 0.03533994 | CV14: 32.93 | CW14: =(CV14-CQ14)/CQ14 -> 0.00030376671 | CX14: =CW14*CW14 -> 9.2274212e-08 | CY14: =CV14*$L14 -> 63411.89 | CZ14: =CY14/$CY$19 -> 0.035399881 | DA14: 32.71 | DB14: =(DA14-CV14)/CV14 -> -0.0066808381 | DC14: =DB14*CZ14 -> -0.00023650088 | DD14: =DA14*$L14 -> 62988.245 | DE14: =DD14/$DD$19 -> 0.035283335 | DF14: 33.43 | DG14: =(DF14-DA14)/DA14 -> 0.022011617 | DH14: =DG14*DE14 -> 0.00077664327 | DI14: =DF14*$L14 -> 64374.718 | DJ14: =DI14/$DI$19 -> 0.034974273 | DK14: 33.43 | DL14: =(DK14-DF14)/DF14 -> 0 | DM14: =DL14*DJ14 -> 0 | DN14: =DK14*$L14 -> 64374.718 | DO14: =DN14/$DN$19 -> 0.035340041 | DP14: 32.42 | DQ14: =(DP14-DK14)/DK14 -> -0.030212384 | DR14: =DQ14*DO14 -> -0.0010677069 | DS14: =DP14*$L14 -> 62429.805 | DT14: =DS14/$DS$19 -> 0.034537979 | DU14: 33.37 | DV14: =(DU14-DP14)/DP14 -> 0.029302899 | DW14: =DV14*DV14 -> 0.00085865992 | DX14: =DU14*$L14 -> 64259.179 | DY14: =DX14/$DX$19 -> 0.034866461 | DZ14: 33.84 | EA14: =(DZ14-DU14)/DU14 -> 0.014084507 | EB14: =EA14*DY14 -> 0.00049107692 | EC14: =DZ14*$L14 -> 65164.238 | ED14: =EC14/$EC$19 -> 0.035150444 | EE14: 34.03 | EF14: =(EE14-DZ14)/DZ14 -> 0.0056146572 | EG14: =EF14*ED14 -> 0.00019735769 | EH14: =EE14*$L14 -> 65530.113 | EI14: =EH14/$EH$19 -> 0.035448723 | EJ14: 35.58 | EK14: =(EJ14-EE14)/EE14 -> 0.045548046 | EL14: =EK14*EI14 -> 0.0016146201 | EM14: =EJ14*$L14 -> 68514.881 | EN14: =EM14/$EM$19 -> 0.036418963 | EO14: 35.23 | EP14: =(EO14-EJ14)/EJ14 -> -0.0098369871 | EQ14: =EP14*EN14 -> -0.00035825287 | ER14: =EO14*$L14 -> 67840.901 | ES14: =ER14/$ER$19 -> 0.035761677 | ET14: 35.09 | EU14: =(ET14-EO14)/EO14 -> -0.0039738859 | EV14: =EU14*EU14 -> 1.5791769e-05 | EW14: =ET14*$L14 -> 67571.309 | EX14: =EW14/$EW$19 -> 0.035847485 | EY14: 35.38 | EZ14: =(EY14-ET14)/ET14 -> 0.0082644628 | FA14: =EZ14*EX14 -> 0.00029626021 | FB14: =EY14*$L14 -> 68129.75 | FC14: =FB14/$FB$19 -> 0.035966781 | FD14: 34.95 | FE14: =(FD14-EY14)/EY14 -> -0.012153759 | FF14: =FE14*FC14 -> -0.00043713159 | FG14: =FD14*$L14 -> 67301.717 | FH14: =FG14/$FG$19 -> 0.03617412 | FI14: 34.9 | FJ14: =(FI14-FD14)/FD14 -> -0.0014306152 | FK14: =FJ14*FH14 -> -5.1751245e-05 | FL14: =FI14*$L14 -> 67205.434 | FM14: =FL14/$FL$19 -> 0.035911748 | FN14: 34.47 | FO14: =(FN14-FI14)/FI14 -> -0.012320917 | FP14: =FO14*FM14 -> -0.00044246566 | FQ14: =FN14*$L14 -> 66377.402 | FR14: =FQ14/$FQ$19 -> 0.035359389 | FS14: 34.01 | FT14: =(FS14-FN14)/FN14 -> -0.013344938 | FU14: =FT14*FR14 -> -0.00047186885 | FV14: =FS14*$L14 -> 65491.599 | FW14: =FV14/$FQ$19 -> 0.034887521 | FX14: 34.1 | FY14: =(FX14-FS14)/FS14 -> 0.0026462805 | FZ14: =FY14*FW14 -> 9.2322165e-05 | GA14: =FX14*$L14 -> 65664.909 | GB14: =GA14/$GA$19 -> 0.0355429 | GC14: 34.18 | GD14: =(GC14-FX14)/FX14 -> 0.0023460411 | GE14: =GD14*GB14 -> 8.3385102e-05 | GF14: =GC14*$L14 -> 65818.961 | GG14: =GF14/$GF$19 -> 0.035363203 | GH14: 34.45 | GI14: =(GH14-GC14)/GC14 -> 0.0078993563 | GJ14: =GI14*GG14 -> 0.00027934654 | GK14: =GH14*$L14 -> 66338.889 | GL14: =GK14/$GK$19 -> 0.035575907 | GM14: 34.37 | GN14: =(GM14-GH14)/GH14 -> -0.0023222061 | GO14: =GN14*GN14 -> 5.3926412e-06 | GP14: =GM14*$L14 -> 66184.836 | GQ14: =GP14/$GP$19 -> 0.036004806 | GR14: 34.2 | GS14: =(GR14-GM14)/GM14 -> -0.004946174 | GT14: =GS14*GQ14 -> -0.00017808604 | GU14: =GR14*$L14 -> 65857.474 | GV14: =GU14/$GU$19 -> 0.036032682 | GW14: 34.03 | GX14: =(GW14-GR14)/GR14 -> -0.0049707602 | GY14: =GX14*GV14 -> -0.00017910982 | GZ14: =GW14*$L14 -> 65530.113 | HA14: =GZ14/$GZ$19 -> 0.035953616 | HB14: 33.47 | HC14: =(HB14-GW14)/GW14 -> -0.016456068 | HD14: =HC14*HA14 -> -0.00059165516 | HE14: =HB14*$L14 -> 64451.745 | HF14: =HE14/$GF$19 -> 0.034628625 | HG14: 33.76 | HH14: =(HG14-HB14)/HB14 -> 0.0086644756 | HI14: =HH14*HF14 -> 0.00030003888 | HJ14: =HG14*$L14 -> 65010.185 | HK14: =HJ14/$HJ$19 -> 0.036064329 | HL14: 33.8 | HM14: =(HL14-HG14)/HG14 -> 0.0011848341 | HN14: =HM14*HM14 -> 1.4038319e-06 | HO14: =HL14*$L14 -> 65087.211 | HP14: =HO14/$HO$19 -> 0.035349594
